


golang中defer,panic,recover是很常用的三个特性，三者一起使用可以充当其他语言中try…catch…的角色，而defer本身又像其他语言的析构函数


panic和recover
===============
- func panic(v interface{})   
中英文说明
```sh
The panic built-in function stops normal execution of the current goroutine.When a function F calls panic, normal execution of F stops immediately.Any functions whose execution was deferred by F are run in the usual way, and then F returns to its caller. To the caller G, the invocation of F then behaves like a call to panic,terminating G's execution and running any deferred functions.This continues until all functions in the executing goroutine have stopped,in reverse order. At that point, the program is terminated and the error condition is reported,including the value of the argument to panic. This termination sequence is called panicking and can be controlled by the built-in function recover.
```
panic内置函数停止当前goroutine的正常执行，当函数F调用panic时，函数F的正常执行被立即停止，然后运行所有在F函数中的defer函数，然后F返回到调用他的函数对于调用者G，F函数的行为就像panic一样，终止G的执行并运行G中所defer函数，此过程会一直继续执行到goroutine所有的函数。panic可以通过内置的recover来捕获。

- func recover() interface{}  
中英文说明
```sh
The recover built-in function allows a program to manage behavior of a panicking goroutine. Executing a call to recover inside a deferred function (but not any function called by it) stops the panicking sequence by restoring normal execution and retrieves the error value passed to the call of panic. If recover is called outside the deferred function it will not stop a panicking sequence. In this case, or when the goroutine is not panicking, or if the argument supplied to panic was nil, recover returns nil. Thus the return value from recover reports whether the goroutine is panicking.
```
recover内置函数用来管理含有panic行为的goroutine，recover运行在defer函数中，获取panic抛出的错误值，并将程序恢复成正常执行的状态。如果在defer函数之外调用recover，那么recover不会停止并且捕获panic错误如果goroutine中没有panic或者捕获的panic的值为nil，recover的返回值也是nil。由此可见，recover的返回值表示当前goroutine是否有panic行为

注意：recover()返回的是interface{}类型，而不是go中的error类型，如果使用recover()的返回值调用xx.Error()，会编译错误


使用例子：
-----------------
```golang
func F() {
	defer initRecover()

    fmt.Println("a")
	panic("I am a panic")

    fmt.Println("b")
}

func initRecover() func() {
	return func() {
		if err := recover(); err != nil {
            // 拼装错误栈信息(错误文件、报错行号)
			var stacktrace string
			for i := 1; ; i++ {
				_, f, l, got := runtime.Caller(i)
				if !got {
					break
				}
				stacktrace += fmt.Sprintf("%s:%d\n", f, l)
			}
			//when stack finishes
			logMessage := fmt.Sprintf("Trace: %s\n", err)
			logMessage += fmt.Sprintf("\n%s", stacktrace)
			println(logMessage)

			//有些监控脚本，会以执行状态来监控脚本是否成功。如shell脚本：0正常 1失败
			os.Exit(1)
		}
	}
}
```


这里有几个需要注意的问题，通过例子表现


1、defer 表达式的函数如果定义在 panic 后面，该函数在 panic 后就无法被执行到
----------------
在defer前panic
```golang
func main() {
    panic("a")
    defer func() {
        fmt.Println("b")
    }()
}
```
结果，b没有被打印出来：
```sh
panic: a

goroutine 1 [running]:
main.main()
    /xxxxx/src/xxx.go:50 +0x39
exit status 2
```

而在defer后panic
```golang
func main() {
    defer func() {
        fmt.Println("b")
    }()
    panic("a")
}
```
结果，b被正常打印：
```sh
b
panic: a

goroutine 1 [running]:
main.main()
    /xxxxx/src/xxx.go:50 +0x39
exit status 2
```


2、F中出现panic时，F函数会立刻终止，不会执行F函数内panic后面的内容，但不会立刻return，而是调用F的defer，如果F的defer中有recover捕获，则F在执行完defer后正常返回，调用函数F的函数G继续正常执行
----------------
```golang
func G() {
    defer func() {
        fmt.Println("c")
    }()
    F()
    fmt.Println("继续执行")
}

func F() {
    defer func() {
        if err := recover(); err != nil {
            fmt.Println("捕获异常:", err)
        }
        fmt.Println("b")
    }()
    panic("a")
}
```
结果：
```sh
捕获异常: a
b
继续执行
c
```


3、如果F的defer中无recover捕获，则将panic抛到G中，G函数会立刻终止，不会执行G函数内后面的内容，但不会立刻return，而调用G的defer...以此类推
----------------
```golang
func G() {
    defer func() {
        if err := recover(); err != nil {
            fmt.Println("捕获异常:", err)
        }
        fmt.Println("c")
    }()
    F()
    fmt.Println("继续执行")
}

func F() {
    defer func() {
        fmt.Println("b")
    }()
    panic("a")
}
```
结果：
```sh
b
捕获异常: a
c
```


4、如果一直没有recover，抛出的panic到当前goroutine最上层函数时，程序直接异常终止
----------------
```golang
func G() {
    defer func() {
        fmt.Println("c")
    }()
    F()
    fmt.Println("继续执行")
}

func F() {
    defer func() {
        fmt.Println("b")
    }()
    panic("a")
}
```
结果：
```sh
b
c
panic: a

goroutine 1 [running]:
main.F()
    /xxxxx/src/xxx.go:61 +0x55
main.G()
    /xxxxx/src/xxx.go:53 +0x42
exit status 2
```


5、recover都是在当前的goroutine里进行捕获的，这就是说，对于创建goroutine的外层函数，如果goroutine内部发生panic并且内部没有用recover，外层函数是无法用recover来捕获的，这样会造成程序崩溃
----------------
```golang
func G() {
    defer func() {
        //goroutine外进行recover
        if err := recover(); err != nil {
            fmt.Println("捕获异常:", err)
        }
        fmt.Println("c")
    }()
    //创建goroutine调用F函数
    go F()
    time.Sleep(time.Second)
}

func F() {
    defer func() {
        fmt.Println("b")
    }()
    //goroutine内部抛出panic
    panic("a")
}
```
结果：
```sh
b
panic: a

goroutine 5 [running]:
main.F()
    /xxxxx/src/xxx.go:67 +0x55
created by main.main
    /xxxxx/src/xxx.go:58 +0x51
exit status 2
```


6、recover返回的是interface{}类型而不是go中的 error 类型，如果外层函数需要调用err.Error()，会编译错误，也可能会在执行时panic
----------------
```golang
func main() {
    defer func() {
        if err := recover(); err != nil {
            fmt.Println("捕获异常:", err.Error())
        }
    }()
    panic("a")
}
```

编译错误，结果：
```sh
err.Error undefined (type interface {} is interface with no methods)
```

```golang
func main() {
    defer func() {
        if err := recover(); err != nil {
            fmt.Println("捕获异常:", fmt.Errorf("%v", err).Error())
        }
    }()
    panic("a")
}
```
结果：
```sh
捕获异常: a
```